Workbook

Sheet 0.1g PET, 2H
D3: Components | E3: Molar mass(g/mol) | F3: Boiling point(°C) | K3: Experimental Condition | M3: 0.1g PET, 0.5M PMA, 10ml(1M H2SO4 : DMSO = 1:1 v/v)
D4: PMA | E4: 1825.25 | F4: -
D5: H2SO4 | E5: 98.08 | F5: 337
D6: DMSO | E6: 78.13 | F6: 189 | N6: Reaction time(1Batch, hour) | O6: 2 | U6: Scaling factor | V6: 0.6 | AA6: Scaling factor | AB6: 0.6
D7: H2O | E7: 18.016 | F7: 100 | L7: Material | M7: Experimental Flow rate(g) | N7: Scale-up Flow rate(kg/2h) | O7: Scale-up Flow rate(kg/y) | R7: CAPEX (Equipment) | U7: CEPCI(2016) | V7: 541.7 | Y7: CAPEX (Equipment) | AA7: CEPCI(2016) | AB7: 541.7
D8: TPA | E8: 166.13 | F8: - | K8: Input | L8: PET | M8: =M19 -> 0.1 | N8: 1000 | O8: =N8*(24/$O$6)*365*$L$59 -> 3504000 | U8: CEPCI(2023) | V8: 800.8 | AA8: CEPCI(2023) | AB8: 800.8
D9: FA | E9: 46.03 | F9: 100.8 | L9: PMA | M9: =0.5/1000*10*E4 -> 9.12625 | N9: =M9*($N$8/$M$8) -> 91262.5 | O9: =N9 -> 91262.5 | R9: Equipment | S9: Installation Factor | T9: Capital Cost(2016$, 6.25 ton PET) | V9: Capital Cost(2023$, 1 ton PET) | Y9: Equipment | Z9: Capital Cost(2023$, 1 ton PET) | AA9: Capital Cost(2023$, 5 ton PET) | AB9: Capital Cost(2023$, 10 ton PET)
D10: H2 | E10: 2.016 | F10: -252.9 | L10: H2SO4 | M10: =5/1000*E5 -> 0.4904 | N10: =M10*($N$8/$M$8) -> 4904 | O10: =N10 -> 4904 | T10: Equipment Cost | U10: Installed Cost | V10: Installed Cost | Z10: Installed Cost | AA10: Installed Cost | AB10: Installed Cost
L11: DMSO | M11: =5*E15 -> 5.5 | N11: =M11*($N$8/$M$8) -> 55000 | O11: =N11+N11*(100-L63)*(24/O6)*365*L59 -> 247720 | R11: Feedstock Pretreatment | Y11: Feedstock Pretreatment
L12: H2O | M12: =5*E14-M10 -> 4.8096 | N12: =M12*($N$8/$M$8) -> 48096 | O12: =N12*(24/$O$6)*365*$L$59 -> 1.6852838e+08 | R12: Conveyor transfer system | S12: 1.7 | T12: 3933582 | U12: =S12*T12 -> 6687089.4 | V12: =U12*(1/6.25)^($V$6)*($V$8/$V$7) -> 3292110.1 | Y12: Conveyor transfer system | Z12: =V12 -> 3292110.1 | AA12: =Z12*(5/1)^$AB$6 -> 8646818.6 | AB12: =Z12*(10/1)^$AB$6 -> 13106126
D13: Density(g/mL, 25°C) | K13: Output | L13: TPA | M13: =$M$8*N20 -> 0.0863876 | N13: =M13*($N$8/$M$8) -> 863.876 | O13: =N13*(24/$O$6)*365*$L$59 -> 3027021.5 | R13: Truck dumper package | S13: 1.7 | T13: 224887 | U13: =S13*T13 -> 382307.9 | V13: =U13*(1/6.25)^($V$6)*($V$8/$V$7) -> 188213.38 | Y13: Truck dumper package | Z13: =V13 -> 188213.38 | AA13: =Z13*(5/1)^$AB$6 -> 494347.67 | AB13: =Z13*(10/1)^$AB$6 -> 749290.96
D14: 1M H2SO4 | E14: 1.06 | L14: FA | M14: =$M$8*N21 -> 0.0405064 | N14: =M14*($N$8/$M$8) -> 405.064 | O14: =N14*(24/$O$6)*365*$L$59 -> 1419344.3 | R14: Dust collection system | S14: 1.7 | T14: 56872 | U14: =S14*T14 -> 96682.4 | V14: =U14*(1/6.25)^($V$6)*($V$8/$V$7) -> 47597.555 | Y14: Dust collection system | Z14: =V14 -> 47597.555 | AA14: =Z14*(5/1)^$AB$6 -> 125016.3 | AB14: =Z14*(10/1)^$AB$6 -> 189489.28
D15: DMSO | E15: 1.1 | L15: H2 | M15: =$M$8*N22 -> 0.00532224 | N15: =M15*($N$8/$M$8) -> 53.2224 | O15: =N15*(24/$O$6)*365*$L$59 -> 186491.29 | R15: Feedstock storage dome | S15: 1.7 | T15: 711158 | U15: =S15*T15 -> 1208968.6 | V15: =U15*(1/6.25)^($V$6)*($V$8/$V$7) -> 595185.36 | Y15: Feedstock storage dome | Z15: =V15 -> 595185.36 | AA15: =Z15*(5/1)^$AB$6 -> 1563270.9 | AB15: =Z15*(10/1)^$AB$6 -> 2369475.6
R16: Shredder | S16: 1.7 | T16: 210000 | U16: =S16*T16 -> 357000 | V16: =U16*(1/6.25)^($V$6)*($V$8/$V$7) -> 175754.09 | Y16: Shredder | Z16: =V16 -> 175754.09 | AA16: =Z16*(5/1)^$AB$6 -> 461623 | AB16: =Z16*(10/1)^$AB$6 -> 699689.63
R17: Extruder | S17: 1.7 | T17: 2409639 | U17: =S17*T17 -> 4096386.3 | V17: =U17*(1/6.25)^($V$6)*($V$8/$V$7) -> 2016685.3 | Y17: Extruder | Z17: =V17 -> 2016685.3 | AA17: =Z17*(5/1)^$AB$6 -> 5296879.9 | AB17: =Z17*(10/1)^$AB$6 -> 8028568.6
D18: Components | E18: Cp(J/g·°C) | F18: ΔHvap(J/g) | K18: Feedstock & Product | L18: Mole(mol) | M18: Mass(g) | N18: Yield | R18: Microgranulator | S18: 1.7 | T18: 674295 | U18: =S18*T18 -> 1146301.5 | V18: =U18*(1/6.25)^($V$6)*($V$8/$V$7) -> 564333.82 | Y18: Microgranulator | Z18: =V18 -> 564333.82 | AA18: =Z18*(5/1)^$AB$6 -> 1482238.5 | AB18: =Z18*(10/1)^$AB$6 -> 2246653.4
D19: H2SO4 | E19: 1.34 | F19: 570.96 | K19: Input PET | L19: - | M19: 0.1 | N19: - | R19: Feedstock Pretreatment total($) | T19: =SUM(T12:T18) -> 8220433 | U19: =SUM(U12:U18) -> 13974736 | V19: =SUM(V12:V18) -> 6879879.5 | Y19: Feedstock Pretreatment total($) | Z19: =V19 -> 6879879.5 | AA19: =Z19*(5/1)^$AB$6 -> 18070195 | AB19: =Z19*(10/1)^$AB$6 -> 27389294
D20: DMSO | E20: 1.91 | F20: 677.08 | K20: Output TPA | L20: =0.00052 -> 0.00052 | M20: =L20*E8 -> 0.0863876 | N20: =M20/$M$19 -> 0.863876 | R20: PET Depolymerization | Y20: PET Depolymerization
D21: H2O | E21: 4.18 | F21: 2256.45 | K21: Output FA | L21: 0.00088 | M21: =L21*E9 -> 0.0405064 | N21: =M21/$M$19 -> 0.405064 | R21: Small particle conveyor | S21: 1 | T21: 820543 | U21: =S21*T21 -> 820543 | V21: =U21*(1/6.25)^($V$6)*($V$8/$V$7) -> 403960.19 | Y21: Small particle conveyor | Z21: =V21 -> 403960.19 | AA21: =Z21*(5/1)^$AB$6 -> 1061012.7 | AB21: =Z21*(10/1)^$AB$6 -> 1608194.5
D22: FA | E22: 2.15 | F22: 1005.9 | K22: Output H2 | L22: =3*L21 -> 0.00264 | M22: =L22*E10 -> 0.00532224 | N22: =M22/$M$19 -> 0.0532224 | R22: PMA storage and transfer | S22: 1.97 | T22: 294648 | U22: =S22*T22 -> 580456.56 | V22: =U22*(1/6.25)^($V$6)*($V$8/$V$7) -> 285763.62 | Y22: PMA storage and transfer | Z22: =V22 -> 285763.62 | AA22: =Z22*(5/1)^$AB$6 -> 750566.1 | AB22: =Z22*(10/1)^$AB$6 -> 1137645.5
R23: Water recirculation pump | S23: 2.3 | T23: 6417 | U23: =S23*T23 -> 14759.1 | V23: =U23*(1/6.25)^($V$6)*($V$8/$V$7) -> 7266.0284 | Y23: Water recirculation pump | Z23: =V23 -> 7266.0284 | AA23: =Z23*(5/1)^$AB$6 -> 19084.426 | AB23: =Z23*(10/1)^$AB$6 -> 28926.58
R24: Depolymerization reactor(7) | S24: 1.98 | T24: 5837187 | U24: =S24*T24 -> 11557630 | V24: =U24*(1/6.25)^($V$6)*($V$8/$V$7) -> 5689918.1 | Y24: Depolymerization reactor(7) | Z24: =V24 -> 5689918.1 | AA24: =Z24*(5/1)^$AB$6 -> 14944728 | AB24: =Z24*(10/1)^$AB$6 -> 22651972
D25: Heat duty calculation | E25: Heat duty(J) | F25: Heat duty(GJ) | K25: Electrolyzer | L25: H2 production | R25: Storage tanks | S25: 1.93 | T25: 102746 | U25: =S25*T25 -> 198299.78 | V25: =U25*(1/6.25)^($V$6)*($V$8/$V$7) -> 97624.641 | Y25: Storage tanks | Z25: =V25 -> 97624.641 | AA25: =Z25*(5/1)^$AB$6 -> 256413.83 | AB25: =Z25*(10/1)^$AB$6 -> 388650.7
D26: Reactor(100°C) → Electrolyzer(25°C) | E26: =-75*1000*($N$10*E19+$N$11*E20+$N$12*E21+$N$14*E22)-F21*N12-F22*N14 -> -2.3623948e+10 | F26: =E26/10^9 -> -23.623948 | K26: Current Density (mA/cm2) | L26: 125 | R26: Reactor effluent cooler | S26: 3.9 | T26: 21905 | U26: =S26*T26 -> 85429.5 | V26: =U26*(1/6.25)^($V$6)*($V$8/$V$7) -> 42057.658 | Y26: Reactor effluent cooler | Z26: =V26 -> 42057.658 | AA26: =Z26*(5/1)^$AB$6 -> 110465.61 | AB26: =Z26*(10/1)^$AB$6 -> 167434.55
D27: Electrolyzer(25°C) → Vessel(180°C) | E27: =155*1000*($N$10*E19+$N$11*E20+$N$12*E21+$N$14*E22)+F21*N12+F22*N14 -> 4.870663e+10 | F27: =E27/10^9 -> 48.70663 | K27: Cell Voltage(V) | L27: 1.2 | R27: Caustic storage and transfer | S27: 1.97 | T27: 138836 | U27: =S27*T27 -> 273506.92 | V27: =U27*(1/6.25)^($V$6)*($V$8/$V$7) -> 134649.75 | Y27: Caustic storage and transfer | Z27: =V27 -> 134649.75 | AA27: =Z27*(5/1)^$AB$6 -> 353661.3 | AB27: =Z27*(10/1)^$AB$6 -> 536050.29
D28: Vessel(180°C) → Reactor(100°C) | E28: =-80*1000*($N$10*E19+$N$11*E20) -> -8929708800 | F28: =E28/10^9 -> -8.9297088 | K28: Faradaic Efficiency(%) | L28: 0.95 | R28: PET Depolymerization total($) | T28: =SUM(T21:T27) -> 7222282 | U28: =SUM(U21:U27) -> 13530625 | V28: =SUM(V21:V27) -> 6661240 | Y28: PET Depolymerization total($) | Z28: =V28 -> 6661240 | AA28: =Z28*(5/1)^$AB$6 -> 17495932 | AB28: =Z28*(10/1)^$AB$6 -> 26518874
D29: Total Heat duty | E29: =SUM(E26:E28) -> 16152973408 | F29: =E29/10^9 -> 16.152973 | R29: TPA Filteration & Crystallization | Y29: TPA Filteration & Crystallization
R30: Solids filter package | S30: 1.74 | T30: 2250175 | U30: =S30*T30 -> 3915304.5 | V30: =U30*(1/6.25)^($V$6)*($V$8/$V$7) -> 1927537.2 | Y30: Solids filter package | Z30: =V30 -> 1927537.2 | AA30: =Z30*(5/1)^$AB$6 -> 5062730 | AB30: =Z30*(10/1)^$AB$6 -> 7673663.7
K31: Required Electrolyzer Area(m2) | L31: =(N15*1000/E10)*2*96485/(O6*3600*L28*L26*10) -> 595.83719 | R31: rTPA crystallizer | S31: 2.5 | T31: 2868818 | U31: =S31*T31 -> 7172045 | V31: =U31*(1/6.25)^($V$6)*($V$8/$V$7) -> 3530857.8 | Y31: rTPA crystallizer | Z31: =V31 -> 3530857.8 | AA31: =Z31*(5/1)^$AB$6 -> 9273896.1 | AB31: =Z31*(10/1)^$AB$6 -> 14056598
E32: Material Unit Prices | K32: Required Electrolysis Energy(kWh/y) | L32: =O15*L38 -> 5949072.1 | R32: rTPA centrifuge | S32: 2.3 | T32: 639362 | U32: =S32*T32 -> 1470532.6 | V32: =U32*(1/6.25)^($V$6)*($V$8/$V$7) -> 723955.51 | Y32: rTPA centrifuge | Z32: =V32 -> 723955.51 | AA32: =Z32*(5/1)^$AB$6 -> 1901489.3 | AB32: =Z32*(10/1)^$AB$6 -> 2882118.8
E33: Components | F33: Low Cost($/kg) | G33: High Cost($/kg) | H33: Ref | R33: rTPA crystals dryer | S33: 1.5 | T33: 923378 | U33: =S33*T33 -> 1385067 | V33: =U33*(1/6.25)^($V$6)*($V$8/$V$7) -> 681880.08 | Y33: rTPA crystals dryer | Z33: =V33 -> 681880.08 | AA33: =Z33*(5/1)^$AB$6 -> 1790977 | AB33: =Z33*(10/1)^$AB$6 -> 2714613.5
D34: Input | E34: Industrial PET | F34: 0.25 | G34: 0.4 | H34: ICIS 2024 | R34: TPA Filteration & Crystallization total($) | T34: =SUM(T30:T33) -> 6681733 | U34: =SUM(U30:U33) -> 13942949 | V34: =SUM(V30:V33) -> 6864230.5 | Y34: TPA Filteration & Crystallization total($) | Z34: =V34 -> 6864230.5 | AA34: =Z34*(5/1)^$AB$6 -> 18029092 | AB34: =Z34*(10/1)^$AB$6 -> 27326994
E35: Waste PET | F35: 0 | G35: 0.1 | H35: Recycling Market 2024 | K35: Assumptions | L35: Price | M35: Ref | R35: Electrolysis | Y35: Electrolysis
E36: Phosphomolybdic Acid(PMA) | F36: =0.01 -> 0.01 | G36: - | H36: Made-in-China | K36: Electrolyzer($/m^2) | L36: 10000 | M36: Nat Commun 12, 4679 (2021) | R36: Electrolyzer | S36: - | T36: - | U36: - | V36: =L31*L36 -> 5958371.9 | Y36: Electrolyzer | Z36: =V36 -> 5958371.9 | AA36: =Z36*(5/1)^$AB$6 -> 15649830 | AB36: =Z36*(10/1)^$AB$6 -> 23720706
E37: H2SO4 | F37: 0.037 | G37: - | H37: Made-in-China | K37: Electricity($/kWh) | L37: 0.0953 | M37: Kepco data | R37: H2 storage tank | S37: 1.3 | T37: 600000 | U37: =S37*T37 -> 780000 | V37: =U37*(1/6.25)^($V$6)*($V$8/$V$7) -> 384000.53 | Y37: H2 storage tank | Z37: =V37 -> 384000.53 | AA37: =Z37*(5/1)^$AB$6 -> 1008588.1 | AB37: =Z37*(10/1)^$AB$6 -> 1528733.6
E38: Dimethyl Sulfoxide(DMSO) | F38: 1.5 | G38: - | H38: Echemi | K38: H2 Electrolysis Energy(kWh/kg H2) | L38: 31.9 | M38: - | R38: Electrolysis total($) | T38: =SUM(T36:T37) -> 600000 | U38: =SUM(U36:U37) -> 780000 | V38: =SUM(V36:V37) -> 6342372.5 | Y38: Electrolysis total($) | Z38: =V38 -> 6342372.5 | AA38: =Z38*(5/1)^$AB$6 -> 16658418 | AB38: =Z38*(10/1)^$AB$6 -> 25249440
E39: H2O | F39: 0.00022 | G39: - | H39: Nat Commun 12, 4679 (2021) | K39: Reactor heating(100°C) Electricity($/ton PET) | L39: 17 | M39: - | R39: OSBL | Y39: OSBL
D40: Output | E40: Terephthalic Acid(TPA) | F40: 0.94 | G40: - | H40: - | K40: Mechanical Crushing Electricity($/ton PET) | L40: 13 | M40: - | R40: Outside battery limits capital(25% of ISBL) | T40: =SUM(T$19,T$28,T$34,T$38)*0.25 -> 5681112 | U40: =SUM(U$19,U$28,U$34,U$38)*0.25 -> 10557078 | V40: =SUM(V$19,V$28,V$34,V$38)*0.25 -> 6686930.6 | Y40: Outside battery limits capital(25% of ISBL) | Z40: =V40 -> 6686930.6 | AA40: =SUM(AA$19,AA$28,AA$34,AA$38)*0.25 -> 17563409 | AB40: =SUM(AB$19,AB$28,AB$34,AB$38)*0.25 -> 26621150
E41: Formic Acid(FA) | F41: 0.84 | G41: - | H41: - | K41: Total Catalyst & Membrane cost / Electrolyzer | L41: 0.05 | M41: Nat Commun 12, 4679 (2021) | R41: OSBL total($) | T41: =SUM(T40) -> 5681112 | U41: =SUM(U40) -> 10557078 | V41: =SUM(V40) -> 6686930.6 | Y41: OSBL total($) | Z41: =V41 -> 6686930.6 | AA41: =SUM(AA$19,AA$28,AA$34,AA$38)*0.25 -> 17563409 | AB41: =SUM(AB$19,AB$28,AB$34,AB$38)*0.25 -> 26621150
E42: H2 | F42: 8 | G42: - | H42: - | R42: Total($) | T42: =SUM(T19,T28,T34,T38,T41) -> 28405560 | U42: =SUM(U19,U28,U34,U38,U41) -> 52785388 | V42: =SUM(V19,V28,V34,V38,V41) -> 33434653 | Y42: Total($) | Z42: =SUM(Z19,Z28,Z34,Z38,Z41) -> 33434653 | AA42: =SUM(AA19,AA28,AA34,AA38,AA41) -> 87817046 | AB42: =SUM(AB19,AB28,AB34,AB38,AB41) -> 1.3310575e+08
...

Sheet TEA Summary
B2: PET Degradation Techno-Economic Analysis (TEA) Summary
B3: 0.1g PET, 0.5M PMA, 10ml (1M H₂SO₄ : DMSO = 1:1 v/v), 2H Reaction
B5: 1. Experimental Conditions & Scale-up
B7: Parameter | C7: Experimental (g) | D7: Scale-up (kg/2h) | E7: Annual (kg/y)
B8: PET (Input) | C8: ='0.1g PET, 2H'!M8 -> 0.1 | D8: ='0.1g PET, 2H'!N8 -> 1000 | E8: ='0.1g PET, 2H'!O8 -> 3504000
B9: PMA | C9: ='0.1g PET, 2H'!M9 -> 9.12625 | D9: ='0.1g PET, 2H'!N9 -> 91262.5 | E9: ='0.1g PET, 2H'!O9 -> 91262.5
B10: H₂SO₄ | C10: ='0.1g PET, 2H'!M10 -> 0.4904 | D10: ='0.1g PET, 2H'!N10 -> 4904 | E10: ='0.1g PET, 2H'!O10 -> 4904
B11: DMSO | C11: ='0.1g PET, 2H'!M11 -> 5.5 | D11: ='0.1g PET, 2H'!N11 -> 55000 | E11: ='0.1g PET, 2H'!O11 -> 247720
B12: H₂O | C12: ='0.1g PET, 2H'!M12 -> 4.8096 | D12: ='0.1g PET, 2H'!N12 -> 48096 | E12: ='0.1g PET, 2H'!O12 -> 1.6852838e+08
B13: TPA (Output) | C13: ='0.1g PET, 2H'!M13 -> 0.0863876 | D13: ='0.1g PET, 2H'!N13 -> 863.876 | E13: ='0.1g PET, 2H'!O13 -> 3027021.5
B14: FA (Output) | C14: ='0.1g PET, 2H'!M14 -> 0.0405064 | D14: ='0.1g PET, 2H'!N14 -> 405.064 | E14: ='0.1g PET, 2H'!O14 -> 1419344.3
B15: H₂ (Output) | C15: ='0.1g PET, 2H'!M15 -> 0.00532224 | D15: ='0.1g PET, 2H'!N15 -> 53.2224 | E15: ='0.1g PET, 2H'!O15 -> 186491.29
B17: 2. Key Assumptions
B19: Parameter | C19: Value | D19: Ref
B20: Reaction time (1 Batch) | C20: ='0.1g PET, 2H'!O6 -> 2
B21: Discount rate | C21: ='0.1g PET, 2H'!L56 -> 0.1 | D21: ='0.1g PET, 2H'!M56 -> Joule 5, 2479-2503 (2021)
B22: Lifetime | C22: ='0.1g PET, 2H'!L57 -> 30 | D22: ='0.1g PET, 2H'!M57 -> Joule 5, 2479-2503 (2021)
B23: Capital recovery factor | C23: ='0.1g PET, 2H'!L58 -> 0.10607925
B24: Capacity factor | C24: ='0.1g PET, 2H'!L59 -> 0.8 | D24: ='0.1g PET, 2H'!M59 -> Nat Commun 12, 4679 (2021)
B25: Scaling factor | C25: ='0.1g PET, 2H'!V6 -> 0.6
B26: CEPCI (2016 → 2023) | C26: 541.7 → 800.8
B27: Electrolyzer ($/m²) | C27: ='0.1g PET, 2H'!L36 -> 10000 | D27: ='0.1g PET, 2H'!M36 -> Nat Commun 12, 4679 (2021)
B28: Electricity ($/kWh) | C28: ='0.1g PET, 2H'!L37 -> 0.0953 | D28: ='0.1g PET, 2H'!M37 -> Kepco data
B29: DMSO recovery (%) | C29: ='0.1g PET, 2H'!L63 -> 99.999
B30: PMA recovery (%) | C30: ='0.1g PET, 2H'!L64 -> 100
B32: 3. CAPEX Summary (Equipment + Installation)
B34: Equipment Category | C34: 1 ton PET ($/y) | D34: 5 ton PET ($/y) | E34: 10 ton PET ($/y)
B35: Feedstock Pretreatment | C35: ='0.1g PET, 2H'!V19 -> 6879879.5 | D35: ='0.1g PET, 2H'!AA19 -> 18070195 | E35: ='0.1g PET, 2H'!AB19 -> 27389294
B36: PET Depolymerization | C36: ='0.1g PET, 2H'!V28 -> 6661240 | D36: ='0.1g PET, 2H'!AA28 -> 17495932 | E36: ='0.1g PET, 2H'!AB28 -> 26518874
B37: TPA Filtration & Crystallization | C37: ='0.1g PET, 2H'!V34 -> 6864230.5 | D37: ='0.1g PET, 2H'!AA34 -> 18029092 | E37: ='0.1g PET, 2H'!AB34 -> 27326994
B38: Electrolysis | C38: ='0.1g PET, 2H'!V38 -> 6342372.5 | D38: ='0.1g PET, 2H'!AA38 -> 16658418 | E38: ='0.1g PET, 2H'!AB38 -> 25249440
B39: OSBL (25% of ISBL) | C39: ='0.1g PET, 2H'!V41 -> 6686930.6 | D39: ='0.1g PET, 2H'!AA41 -> 17563409 | E39: ='0.1g PET, 2H'!AB41 -> 26621150
B40: Total Equipment CAPEX | C40: ='0.1g PET, 2H'!V42 -> 33434653 | D40: ='0.1g PET, 2H'!AA42 -> 87817046 | E40: ='0.1g PET, 2H'!AB42 -> 1.3310575e+08
B41: Annualized Equipment CAPEX | C41: ='0.1g PET, 2H'!Z43 -> 3546722.9 | D41: ='0.1g PET, 2H'!AA43 -> 9315566.2 | E41: ='0.1g PET, 2H'!AB43 -> 14119758
B43: Annualized CAPEX - Feedstock (Initial) | C43: ='0.1g PET, 2H'!Z53 -> 83594.073 | D43: ='0.1g PET, 2H'!AA53 -> 417970.36 | E43: ='0.1g PET, 2H'!AB53 -> 835940.73
B44: Annualized CAPEX - FA Distillation | C44: ='0.1g PET, 2H'!AE51 -> 125538.87 | D44: ='0.1g PET, 2H'!AF51 -> 627694.35 | E44: ='0.1g PET, 2H'!AG51 -> 1255388.7
B45: Total Annualized CAPEX | C45: =C41+C43+C44 -> 3755855.8 | D45: =D41+D43+D44 -> 10361231 | E45: =E41+E43+E44 -> 16211087
B47: 4. OPEX Summary (Annual Operating Cost)
B49: OPEX Category | C49: 1 ton PET ($/y) | D49: 5 ton PET ($/y) | E49: 10 ton PET ($/y)
B50: Feedstock - PET | C50: ='0.1g PET, 2H'!Z60 -> 350400 | D50: ='0.1g PET, 2H'!AA60 -> 1752000 | E50: ='0.1g PET, 2H'!AB60 -> 1752000
...
